Workbook

Sheet Read me
B2: SABALIVE QA tracker
B4: What this is | C4: One row per issue or fix. The App tab covers the Flutter app (Android and iOS). The Panel tab covers the admin panel. Summary counts everything automatically.
B5: Where to type | C5: Add new rows at the bottom of App or Panel. Type in any cell of a row, or pick from the dropdown in Type, Severity, Status, Source and Fix needs. Leave Summary and Lists alone unless you are changing a dropdown.
B6: Sr no | C6: Numbers each row. Copy the last number + 1 for a new row.
B7: Reported by / Source | C7: Reported by = the person or party. Source = how it reached you: Owner, Play user, Play Console, App Review, QA tester, Panel user, Investigation.
B8: Type | C8: Bug, Fix, Improvement, Security, Policy, Build/Infra, Question.
B9: Severity | C9: Critical = crash, lost money or data, security, or everyone blocked. High = a main feature broken. Medium = a feature degraded. Low = cosmetic.
B10: Status flow | C10: New > Confirmed > In progress > Fixed (in code) > Released > Verified > Closed. Side exits: Needs decision, Can't reproduce, Won't fix. 'Fixed (in code)' means the change exists but users do not have it yet.
B11: Fix needs | C11: What must happen for users to get the fix: Database migration, Edge function, App build, Panel deploy, Store / console action, or Decision. Combine in the cell when more than one applies.
B12: Fixed in | C12: App version (for example 1.0.0+8) or a git commit. For database fixes, the migration number.
B13: Verified by / date | C13: Who retested, on which build, and when. A fix is not done until a person has seen it work.
B14: Environment | C14: App tab: device model, Android/iOS version, app version and code. Many bugs only appear on one OS version (the back-gesture bug only on Android 16).
B15: Role affected | C15: Panel tab: Super Admin, Master, Global, Country, Sub or Agency. Many panel bugs affect one role only.
B16: Pre-filled rows | C16: The rows already here are the real issues from the October 2026 work, so you can see the format. Dates were left blank where they were not known. Statuses reflect the code and database at the time of writing; nothing marked 'Fixed (in code)' on the App tab has reached the Play Store unless Released is shown.

Sheet Summary
B2: Summary (updates by itself)
B4: Status | C4: App | D4: Panel | E4: Total
B5: =Lists!C2 | C5: =COUNTIF(App!$M$2:$M$400,B5) | D5: =COUNTIF(Panel!$N$2:$N$400,B5) | E5: =C5+D5
B6: =Lists!C3 | C6: =COUNTIF(App!$M$2:$M$400,B6) | D6: =COUNTIF(Panel!$N$2:$N$400,B6) | E6: =C6+D6
B7: =Lists!C4 | C7: =COUNTIF(App!$M$2:$M$400,B7) | D7: =COUNTIF(Panel!$N$2:$N$400,B7) | E7: =C7+D7
B8: =Lists!C5 | C8: =COUNTIF(App!$M$2:$M$400,B8) | D8: =COUNTIF(Panel!$N$2:$N$400,B8) | E8: =C8+D8
B9: =Lists!C6 | C9: =COUNTIF(App!$M$2:$M$400,B9) | D9: =COUNTIF(Panel!$N$2:$N$400,B9) | E9: =C9+D9
B10: =Lists!C7 | C10: =COUNTIF(App!$M$2:$M$400,B10) | D10: =COUNTIF(Panel!$N$2:$N$400,B10) | E10: =C10+D10
B11: =Lists!C8 | C11: =COUNTIF(App!$M$2:$M$400,B11) | D11: =COUNTIF(Panel!$N$2:$N$400,B11) | E11: =C11+D11
B12: =Lists!C9 | C12: =COUNTIF(App!$M$2:$M$400,B12) | D12: =COUNTIF(Panel!$N$2:$N$400,B12) | E12: =C12+D12
B13: =Lists!C10 | C13: =COUNTIF(App!$M$2:$M$400,B13) | D13: =COUNTIF(Panel!$N$2:$N$400,B13) | E13: =C13+D13
B14: =Lists!C11 | C14: =COUNTIF(App!$M$2:$M$400,B14) | D14: =COUNTIF(Panel!$N$2:$N$400,B14) | E14: =C14+D14
B15: All rows | C15: =SUM(C5:C14) | D15: =SUM(D5:D14) | E15: =SUM(E5:E14)
B17: Open items by severity
B18: Severity | C18: App | D18: Panel | E18: Total
B19: =Lists!B2 | C19: =COUNTIFS(App!$G$2:$G$400,$B19,App!$M$2:$M$400,"New")+COUNTIFS(App!$G$2:$G$400,$B19,App!$M$2:$M$400,"Confirmed")+COUNTIFS(App!$G$2:$G$400,$B19,App!$M$2:$M$400,"In progress")+COUNTIFS(App!$G$2:$G$400,$B19,App!$M$2:$M$400,"Needs decision")+COUNTIFS(App!$G$2:$G$400,$B19,App!$M$2:$M$400,"Can't reproduce") | D19: =COUNTIFS(Panel!$G$2:$G$400,$B19,Panel!$N$2:$N$400,"New")+COUNTIFS(Panel!$G$2:$G$400,$B19,Panel!$N$2:$N$400,"Confirmed")+COUNTIFS(Panel!$G$2:$G$400,$B19,Panel!$N$2:$N$400,"In progress")+COUNTIFS(Panel!$G$2:$G$400,$B19,Panel!$N$2:$N$400,"Needs decision")+COUNTIFS(Panel!$G$2:$G$400,$B19,Panel!$N$2:$N$400,"Can't reproduce") | E19: =C19+D19
B20: =Lists!B3 | C20: =COUNTIFS(App!$G$2:$G$400,$B20,App!$M$2:$M$400,"New")+COUNTIFS(App!$G$2:$G$400,$B20,App!$M$2:$M$400,"Confirmed")+COUNTIFS(App!$G$2:$G$400,$B20,App!$M$2:$M$400,"In progress")+COUNTIFS(App!$G$2:$G$400,$B20,App!$M$2:$M$400,"Needs decision")+COUNTIFS(App!$G$2:$G$400,$B20,App!$M$2:$M$400,"Can't reproduce") | D20: =COUNTIFS(Panel!$G$2:$G$400,$B20,Panel!$N$2:$N$400,"New")+COUNTIFS(Panel!$G$2:$G$400,$B20,Panel!$N$2:$N$400,"Confirmed")+COUNTIFS(Panel!$G$2:$G$400,$B20,Panel!$N$2:$N$400,"In progress")+COUNTIFS(Panel!$G$2:$G$400,$B20,Panel!$N$2:$N$400,"Needs decision")+COUNTIFS(Panel!$G$2:$G$400,$B20,Panel!$N$2:$N$400,"Can't reproduce") | E20: =C20+D20
B21: =Lists!B4 | C21: =COUNTIFS(App!$G$2:$G$400,$B21,App!$M$2:$M$400,"New")+COUNTIFS(App!$G$2:$G$400,$B21,App!$M$2:$M$400,"Confirmed")+COUNTIFS(App!$G$2:$G$400,$B21,App!$M$2:$M$400,"In progress")+COUNTIFS(App!$G$2:$G$400,$B21,App!$M$2:$M$400,"Needs decision")+COUNTIFS(App!$G$2:$G$400,$B21,App!$M$2:$M$400,"Can't reproduce") | D21: =COUNTIFS(Panel!$G$2:$G$400,$B21,Panel!$N$2:$N$400,"New")+COUNTIFS(Panel!$G$2:$G$400,$B21,Panel!$N$2:$N$400,"Confirmed")+COUNTIFS(Panel!$G$2:$G$400,$B21,Panel!$N$2:$N$400,"In progress")+COUNTIFS(Panel!$G$2:$G$400,$B21,Panel!$N$2:$N$400,"Needs decision")+COUNTIFS(Panel!$G$2:$G$400,$B21,Panel!$N$2:$N$400,"Can't reproduce") | E21: =C21+D21
B22: =Lists!B5 | C22: =COUNTIFS(App!$G$2:$G$400,$B22,App!$M$2:$M$400,"New")+COUNTIFS(App!$G$2:$G$400,$B22,App!$M$2:$M$400,"Confirmed")+COUNTIFS(App!$G$2:$G$400,$B22,App!$M$2:$M$400,"In progress")+COUNTIFS(App!$G$2:$G$400,$B22,App!$M$2:$M$400,"Needs decision")+COUNTIFS(App!$G$2:$G$400,$B22,App!$M$2:$M$400,"Can't reproduce") | D22: =COUNTIFS(Panel!$G$2:$G$400,$B22,Panel!$N$2:$N$400,"New")+COUNTIFS(Panel!$G$2:$G$400,$B22,Panel!$N$2:$N$400,"Confirmed")+COUNTIFS(Panel!$G$2:$G$400,$B22,Panel!$N$2:$N$400,"In progress")+COUNTIFS(Panel!$G$2:$G$400,$B22,Panel!$N$2:$N$400,"Needs decision")+COUNTIFS(Panel!$G$2:$G$400,$B22,Panel!$N$2:$N$400,"Can't reproduce") | E22: =C22+D22
B23: Open items | C23: =SUM(C19:C22) | D23: =SUM(D19:D22) | E23: =SUM(E19:E22)
B25: Open = New, Confirmed, In progress, Needs decision, Can't reproduce.

Sheet App
A1: Sr no | B1: Date reported | C1: Reported by | D1: Source | E1: Module / screen | F1: Type | G1: Severity | H1: Issue / Fix | I1: Steps to reproduce | J1: Expected vs actual | K1: Environment (device, OS, app version) | L1: Evidence (link) | M1: Status | N1: Assigned to | O1: Fixed in (version / commit) | P1: Fix needs | Q1: Verified by / date | R1: Notes / root cause
A2: 1 | C2: Google Play | D2: Play Console | E2: Permissions / avatar picker | F2: Policy | G2: High | H2: Play 'Photo and Video Permissions' policy. FIX: removed READ_MEDIA_* / READ_EXTERNAL_STORAGE; the avatar picker now uses Android's system Photo Picker; first-run prompt no longer asks for photos/storage/audio. | I2: Play Console > Policy status | J2: Expected: no media permissions declared. Actual: policy issue raised. | K2: Android, Play build | M2: Released | O2: Committed (Oct 2026 batch) | Released: Play 1.0.0+8 (published to everyone 2026-10-13; commit is in tag play-8) | P2: App build | R2: Needs a Play release and re-submission to clear the policy issue. | Status set to Released on 2026-10-14 from git: this commit is in the source of Play 1.0.0+8. Not yet verified by a person.
A3: 2 | C3: Owner | D3: Owner | E3: Live room (host and viewer) | F3: Bug | G3: Medium | H3: Keyboard reopens by itself after using any live option. FIX: unfocus when a route/popup opens over the live; live screens lift manually instead of resizing. | I3: 1. Open chat field in a live. 2. Open any option/sheet. 3. Close it. | J3: Expected: keyboard stays closed. Actual: keyboard reopens. | K3: Android APK | M3: Released | O3: ffb3369 | Released: Play 1.0.0+8 (published to everyone 2026-10-13; commit is in tag play-8) | P3: App build | R3: Test: test/keyboard_focus_test.dart. | Status set to Released on 2026-10-14 from git: this commit is in the source of Play 1.0.0+8. Not yet verified by a person. | The commit is also in tag play-live (the 1.0.0+7 build).
A4: 3 | C4: Owner | D4: Owner | E4: Live room (host) | F4: Bug | G4: High | H4: Host app crashed in a live. Cause NOT identified (no logs). Mitigated the keyboard/platform-view resize; music file picker is another suspect. | I4: Not reproduced | J4: Expected: no crash. Actual: crash. | K4: Android | M4: Can't reproduce | P4: App build | R4: Needs crash logs: add Crashlytics; check Play Console > Android vitals; `adb logcat -b crash`.
A5: 4 | C5: Play user | D5: Play user | E5: Audio room seats | F5: Bug | G5: High | H5: Seat still shows as used after leaving; host not visible; people joining/coming on seats not shown. ROOT CAUSE: old builds' filtered DELETE listeners never see seat removals; the stale-presence sweeper freed the host's seat when its heartbeat lapsed; Realtime does not replay missed events. FIX: server keeps the host seat while the stream heartbeat is fresh (migration 20261004190000, live in prod) + the app re-reads seats from the server every 10 s, on resume and on subscribe. | I5: 1. Join audio room. 2. Take a seat. 3. Leave. 4. Look from another phone. | J5: Expected: seat freed, host visible. Actual: ghost / missing seats. | K5: Old Play build and new APK | M5: Released | O5: 5850a64 (DB) + ee1aed0 (app) | Released: Play 1.0.0+8 (published to everyone 2026-10-13; commit is in tag play-8) | P5: App build | R5: Database part is live. App part ships in 1.0.0+8. | Status set to Released on 2026-10-14 from git: this commit is in the source of Play 1.0.0+8. Not yet verified by a person.
A6: 5 | B6: 2026-10-06 | C6: Owner | D6: Owner | E6: Seat speaking indicator | F6: Bug | G6: Medium | H6: Only your own voice lights your seat; other people's never do. ROOT CAUSE: live_stream_seats.agora_uid / set_seat_agora_uid were 32-bit; about 47% of Agora uids exceed 2^31 (max seen 4,287,323,012), so the call failed silently. FIX: bigint (migration 20261004210000, live in prod) + the app matches uids unsigned. | I6: 1. Two phones in an audio room. 2. One speaks. | J6: Expected: speaker's seat lights on both phones. Actual: only on own phone. | K6: Play + APK | M6: Released | O6: 5850a64 (DB) + ee1aed0 (app) | Released: Play 1.0.0+8 (published to everyone 2026-10-13; commit is in tag play-8) | P6: App build | Q6: DB verified in prod 2026-10-06 | R6: DB part is live for existing builds (users must re-sit or rejoin). Waves UI ships in +8. | Status set to Released on 2026-10-14 from git: this commit is in the source of Play 1.0.0+8. Not yet verified by a person.
A7: 6 | B7: 2026-10-06 | C7: Owner | D7: Owner | E7: Speaking indicator (audio + video live) | F7: Improvement | G7: Medium | H7: Replace the green glow with a circular wave ring like the reference video, on audio-room seats, the seat strip in video lives, and the host's avatar in video lives. | I7: - | J7: Expected: wave ring around the speaker. | K7: App | L7: Reference: GREEN SCREEN spectrum.mp4 | M7: Released | O7: ee1aed0 | Released: Play 1.0.0+8 (published to everyone 2026-10-13; commit is in tag play-8) | P7: App build | R7: Shape is generated (Agora only reports loudness). Runs only while someone is heard. | Status set to Released on 2026-10-14 from git: this commit is in the source of Play 1.0.0+8. Not yet verified by a person.
A8: 7 | B8: 2026-10-06 | C8: Owner | D8: Owner | E8: Live navigation | F8: Bug | G8: High | H8: Android gesture back takes the user out of the live instead of showing leave/end and the options. ROOT CAUSE: app targets Android 16 (targetSdk 36); Flutter did not claim the back gesture with only the home page under the live. FIX: LiveBackGuard. | I8: 1. Join a live. 2. Swipe back. | J8: Expected: leave/end dialog. Actual: leaves the live. | K8: Android 16, gesture navigation | M8: Released | O8: ee1aed0 | Released: Play 1.0.0+8 (published to everyone 2026-10-13; commit is in tag play-8) | P8: App build | R8: Unit-tested only. Verify on a real Android 16 phone with gesture AND button navigation. | Status set to Released on 2026-10-14 from git: this commit is in the source of Play 1.0.0+8. Not yet verified by a person.
A9: 8 | B9: 2026-10-06 | C9: Play user | D9: Play user | E9: Live rooms (performance) | F9: Bug | G9: High | H9: Phone heating. Mitigations: avatar frames show a still when smaller than 48 px; Home reloads once per burst of Realtime events; host clock no longer rebuilds the whole screen each second; host video 24 fps; sigma-70 blur removed from login/onboarding background. | I9: Use live rooms for several minutes | J9: Expected: normal temperature. | K9: Redmi Note 15 5G, HyperOS 3, Android 16 | M9: Released | O9: ee1aed0 | Released: Play 1.0.0+8 (published to everyone 2026-10-13; commit is in tag play-8) | P9: App build | R9: Not measured on a device. Next ideas: thermal-adaptive quality; lower video resolution (see the Agora cost item). | Status set to Released on 2026-10-14 from git: this commit is in the source of Play 1.0.0+8. Not yet verified by a person.
A10: 9 | B10: 2026-10-04 | C10: Play user | D10: Play user | E10: Live rooms (all) | F10: Bug | G10: Critical | H10: Slowness, rooms failing and 'crashes' for many users. ROOT CAUSE: the Agora free quota (10,000 min) was used up. FIX: topped up to 25,000 minutes. | I10: - | J10: Expected: rooms connect. Actual: joins/publishing refused. | K10: All | L10: Agora console screenshot | M10: Closed | O10: Owner top-up | P10: Store / console action | R10: Follow up: HD video is about 2/3 of billed minutes. 25,000 may last only days; see the Agora cost item.
A11: 10 | C11: Investigation | D11: Investigation | E11: Live end time | F11: Bug | G11: Medium | H11: Host-pressed End stored ended_at as local time with no zone, so lives 'ended' hours off (5.5 h in the future in India) and live-hours reports were inflated. FIX: server stamps ended_at; 262 past rows repaired; the app now sends UTC. | I11: - | J11: Expected: ended_at = now. Actual: hours off. | K11: All | M11: Released | O11: 5850a64 (DB) + ee1aed0 | Released: Play 1.0.0+8 (published to everyone 2026-10-13; commit is in tag play-8) | P11: Database migration | Q11: Verified in prod 2026-10-06 (0 bad rows) | R11: Migration 20261004200000 is live. | Status set to Released on 2026-10-14 from git: this commit is in the source of Play 1.0.0+8. Not yet verified by a person.
A12: 11 | C12: Investigation | D12: Investigation | E12: Wallet / purchases | F12: Security | G12: Critical | H12: dev_purchase_coins (an alpha test RPC) let ANY signed-in user mint coins. Never used (0 ledger rows). FIX: execute revoked. | I12: - | J12: Expected: no free coins. Actual: callable. | K12: Backend | M12: Released | O12: 5850a64 | Released: Play 1.0.0+8 (published to everyone 2026-10-13; commit is in tag play-8) | P12: Database migration | Q12: Verified in prod 2026-10-06 | R12: Kept closed on purpose when the rollback was discussed. | Status set to Released on 2026-10-14 from git: this commit is in the source of Play 1.0.0+8. Not yet verified by a person.
A13: 12 | B13: 2026-10-06 | C13: Play user | D13: Play user | E13: Login (Google) | F13: Bug | G13: High | H13: Error 'PlatformException(channel-error, ... google_sign_in_android.GoogleSignInApi.signIn)' on some phones. FIX: fall back to the browser Google sign-in; readable, translated message instead of the raw error. | I13: Tap the Google button | J13: Expected: Google sign-in. Actual: raw error. | K13: Play build; phone model unknown | L13: Screenshot | M13: Released | O13: e5aa4f6 | Released: Play 1.0.0+8 (published to everyone 2026-10-13; commit is in tag play-8) | P13: App build | R13: Real cause on that phone unknown (Play Services?). Email, phone and username login are unaffected. Ask the reporter for model + Android version. | Status set to Released on 2026-10-14 from git: this commit is in the source of Play 1.0.0+8. Not yet verified by a person.
A14: 13 | C14: App Review | D14: App Review | E14: Chat / Rankings | F14: Bug | G14: High | H14: Apple 2.1(a): chat top-right '...' did nothing; the '+' and emoji icons in the chat bar and the Rankings info icon were dead. FIX: '...' opens View profile / Block / Report; dead icons removed. | I14: Open any chat | J14: Expected: working controls. | K14: iPad Air 11 (M3), iPadOS 27 | L14: App Review message | M14: Released | O14: ee1aed0 | Released: Play 1.0.0+8 (published to everyone 2026-10-13; commit is in tag play-8) | P14: App build | R14: Also fixed: the Report sheet overflowed on short screens. | Status set to Released on 2026-10-14 from git: this commit is in the source of Play 1.0.0+8. Not yet verified by a person.
A15: 14 | C15: App Review | D15: App Review | E15: Live (iPad) | F15: Bug | G15: High | H15: Apple 2.1(a): 'live video did not load' and 'most features in the live unresponsive' on iPad. | I15: Open a live on iPad | J15: Expected: video plays. | K15: iPad Air 11 (M3), iPadOS 27 | M15: Can't reproduce | P15: Decision | R15: Probably no host was live during review. Plan: a host live during review + demo login in Review Notes; test on an iPad.
A16: 15 | C16: Owner | D16: Owner | E16: Profile | F16: Bug | G16: Medium | H16: Language tile said 'coming soon'. FIX: opens the language picker (9 languages). | I16: Profile > Language | K16: APK | M16: Released | O16: Oct 4 batch | Released: Play 1.0.0+8 (published to everyone 2026-10-13; commit is in tag play-8) | P16: App build | R16: Status set to Released on 2026-10-14 from git: this commit is in the source of Play 1.0.0+8. Not yet verified by a person.
A17: 16 | C17: Owner | D17: Owner | E17: Profile | F17: Bug | G17: Low | H17: Profile menu grid had a gap. FIX: fixed row height. | I17: Profile screen | K17: APK | M17: Released | O17: Oct 4 batch | Released: Play 1.0.0+8 (published to everyone 2026-10-13; commit is in tag play-8) | P17: App build | R17: Status set to Released on 2026-10-14 from git: this commit is in the source of Play 1.0.0+8. Not yet verified by a person.
A18: 17 | C18: Owner | D18: Owner | E18: Live chat | F18: Bug | G18: Low | H18: 'Left' notice was not styled like 'joined'. FIX: same style. | I18: Join then leave a live | K18: APK | M18: Released | O18: Oct 4 batch | Released: Play 1.0.0+8 (published to everyone 2026-10-13; commit is in tag play-8) | P18: App build | R18: Status set to Released on 2026-10-14 from git: this commit is in the source of Play 1.0.0+8. Not yet verified by a person.
A19: 18 | C19: Owner | D19: Owner | E19: Audio room (host music) | F19: Bug | G19: Medium | H19: Local mp3 player: host could not hear anything. Diagnostics added; cause not found. | I19: Audio room > Music > pick a file | J19: Expected: song plays into the room. | K19: APK | M19: Confirmed | P19: App build | R19: Needs a device test with logs. Music is host-only and audio-room-only.
A20: 19 | C20: Owner | D20: Owner | E20: Wallet / coin sellers | F20: Bug | G20: Low | H20: Coin seller list showed a shop icon, not the user's profile picture. | I20: Wallet > Offline sellers | K20: Older build on the phone | L20: Screenshot | M20: Closed | P20: None | R20: Backend returns the profile; the phone ran an older build.
A21: 20 | B21: 2026-10-05 | C21: App Review | D21: App Review | E21: App Store Connect | F21: Policy | G21: High | H21: Apple 2.3.6: set Age Rating 'Messaging and Chat' = Yes and 'User-Generated Content' = Yes. | I21: App Information > Age Rating | K21: iOS | M21: New | N21: Owner | P21: Store / console action | R21: Owner action in App Store Connect.
A22: 21 | B22: 2026-10-05 | C22: App Review | D22: App Review | E22: App Store Connect | F22: Policy | G22: High | H22: Apple 5.2.1: China internet cultural business licences requested. PLAN: remove China mainland from availability and reply that the app is not offered there. | I22: Pricing and Availability | K22: iOS | M22: New | N22: Owner | P22: Store / console action | R22: Draft reply: scratchpad app-review-reply-draft.md
A23: 22 | B23: 2026-10-05 | C23: App Review | D23: App Review | E23: App Store metadata | F23: Policy | G23: High | H23: Apple 4.1(a): metadata resembles another app. Found: the icon, logo and splash have a red rounded '> LIVE' pill that resembles YouTube's mark. Name, subtitle, keywords, description and screenshots still need checking. | I23: - | K23: iOS | M23: Needs decision | N23: Owner | P23: Store / console action | R23: Needs a cleaned icon file + the App Store Connect text.
A24: 23 | B24: 2026-10-05 | C24: App Review | D24: App Review | E24: Coins / payments | F24: Policy | G24: Critical | H24: Apple 2.1(b) / 3.1.1: the app sells coins through 'Offline Coin Sellers' (cash/UPI over WhatsApp) and a Coin Reseller tool; Buy Coins is switched off. Needs a decision: (A) In-App Purchase on iOS + hide offline selling on iOS, (B) iOS with no way to get coins, (C) hold the iOS release. | I24: - | K24: iOS | M24: Needs decision | N24: Owner | P24: Decision
A25: 24 | C25: Investigation | D25: Investigation | E25: Profile / Live / Home | F25: Improvement | G25: Medium | H25: Visible 'coming soon' placeholders (VIP, Room Effects, Family, PK battles, Voice effects, Room skins, Seat invites, Games, Withdrawals) are a common App Review complaint. Proposal: hide them (at least on iOS). | I25: - | K25: App | M25: Needs decision | N25: Owner | P25: Decision
A26: 25 | C26: Investigation | D26: Investigation | E26: Login (Apple) | F26: Bug | G26: High | H26: Sign in with Apple was not configured when last checked (the button errors). A likely next App Review rejection. | I26: Tap Apple on the login screen | K26: iOS | M26: New | P26: Store / console action | R26: Verify the current state in Supabase Auth > Providers and the Apple developer account.
A27: 26 | B27: 2026-10-04 | C27: Investigation | D27: Investigation | E27: Agora video cost | F27: Improvement | G27: High | H27: HD portrait video (720x1280) is about 2/3 of billed minutes. Options: A) cheaper resolution, B) two-stream mode, C) leave as is. Also a heat factor. | I27: - | K27: All | M27: Needs decision | N27: Owner | P27: Decision | R27: Not changed yet.
A28: 27 | B28: 2026-10-06 | C28: Owner | D28: Owner | E28: Backend (Supabase) | F28: Build/Infra | G28: High | H28: Cached egress is over the free quota: 11.14 / 5 GB (223%). The app re-downloads gift/frame/skin media each launch and each room (no disk cache; video re-streams on every play). FIX (not built): on-device media cache. Or upgrade the plan. | I28: Supabase > Usage | K28: Backend | L28: Dashboard screenshot | M28: Confirmed | P28: App build | R28: Flushing does not reduce the counter; it resets at the next billing cycle.
A29: 28 | B29: 2026-10-05 | C29: Play user | D29: Play user | E29: Backend (Supabase) | F29: Bug | G29: Critical | H29: Production database stopped answering from about 19:33 to 19:54 UTC (every service returned 504 / DatabaseTimeout). Restarting the project fixed it. Cause NOT identified. | I29: - | K29: Backend | M29: Closed | N29: Owner | O29: Project restart | P29: Store / console action | Q29: Owner confirmed all well | R29: Check Logs > Postgres around 19:30 UTC for out-of-memory or too-many-connections lines.
A30: 29 | B30: 2026-10-05 | C30: Play user | D30: Play user | E30: Backend (after db push) | F30: Bug | G30: High | H30: Issues reported on the live Play app after the database push. All 12 Play-app actions replayed against prod passed. There was a brief blip during the push: background jobs timed out 18:53-18:55 UTC. | I30: - | K30: Play build | M30: Can't reproduce | P30: None | Q30: 12-step replay passed 2026-10-06 | R30: Lesson recorded: see the production-safety rules in CLAUDE.md.
A31: 30 | C31: Investigation | D31: Investigation | E31: Release build | F31: Build/Infra | G31: Medium | H31: Signed bundle build failed twice: R8 lost intermediate files (the machine is short of memory with other Flutter tools open), then a stale generated plugin file. Workaround: flutter clean, then build, with other Flutter/IDE windows closed. | I31: flutter build appbundle --release | K31: Mac, 8 GB RAM | M31: Verified | O31: scripts/release/build_play_bundle.sh; close other Flutter / IDE windows first | P31: None | Q31: Claude, 2026-10-13: the signed 1.0.0+8 bundle built and passed the script's checks (Gradle about 156 s) | R31: 1.0.0+8 bundle not built yet. | Built successfully on 2026-10-13 09:56 IST.
A32: 31 | B32: 2026-10-13 | C32: Owner | D32: Owner | E32: Games (Tulasi) | F32: Improvement | G32: High | H32: Games from the Tulasi platform inside the app (Android only): the Games tab, a Games row on Home, and Games in the More menu of audio, video, host and PK rooms. A game opens in a panel at the bottom; the list, pictures and the Games switch update live; games can be hidden or shown from the panel; 18+ notice and date-of-birth rule; balance calls are handled by our backend. | I32: Release controls > Games ON; open the Games tab on an Android phone with 1.0.0+8. | J32: Expected: the shown games open and play with the user's coins. Actual: works; 23 players and 14,056 successful balance calls on 13-14 Oct; the wallet ledger reconciles to the coin. | K32: Android, Play build 1.0.0+8; Tulasi merchant 1503251, Singapore node | M32: Released | O32: 1.0.0+8 (0d550ff); migrations 20261013100000 to 20261013140000; Edge function tulasi; panel main b37c27e | P32: App build, Database migration, Edge function, Panel deploy | Q32: Owner on the staging APK 2026-10-13; production play checked in the data by Claude 2026-10-14; the owner's own production round is still pending | R32: Live since the Games switch was turned ON at 14:01 IST on 2026-10-13 with 10 of the 44 games shown. Android only; an iPhone shows 'coming soon'. Details: sabalive/docs/TULASI_GAMES.md.
A33: 32 | B33: 2026-10-13 | C33: Owner | D33: Owner | E33: Games / live room | F33: Bug | G33: Medium | H33: A game opened from an audio live showed half the game and a black block covering the live; the Games list stayed behind it and the live above was not usable. | I33: Start an audio live > More > Games > open a game. | J33: Expected: a game panel at the bottom with the live visible and usable above it. Actual: a 90% tall sheet with a black top, the Games list still behind it. | K33: Realme RMX1992 (Android), staging APK 1.0.0+8 of 2026-10-13 | M33: Released | O33: 1.0.0+8 (0d550ff): GamePanelRoute + showGamePanel; the panel height is read from the game page | P33: App build | Q33: Owner, staging APK built 07:11 IST 2026-10-13 ('fix is done'); not yet on the Play build | R33: ROOT CAUSE: the games are Cocos canvases that keep the screen width and hang from the bottom, so extra height shows black; every game reports 750x1334 until its assets finish loading, so that value is ignored for 90 s. Measured: Teen Patti Gold, Dragon Tiger Battle, Lucky99 square; Greedy and Roulette 1.6x tall.
A34: 33 | B34: 2026-10-13 | C34: Owner | D34: Investigation | E34: Tulasi push (Sync Game List) | F34: Build/Infra | G34: High | H34: Sync Game List in the Tulasi dashboard said 'Sync game list fail'. Two causes: our function copied every picture before answering (15 s), and decrypting the full 44-game push with pure-JavaScript RSA exceeded the Edge Function CPU limit (HTTP 546). FIX: answer first and copy pictures in the background; native RSA decryption; accept the platform's real payload (no status field, relative picture paths). | I34: Tulasi dashboard > Merchant Game Config > Sync Game List > Confirm. | J34: Expected: success and the list in our database. Actual: fail, nothing written. | K34: Supabase Edge Function tulasi (staging, then production) | M34: Verified | O34: tulasi function (commits up to 5771196); migration 20261013140000 | P34: Edge function, Database migration | Q34: Claude, 2026-10-13: the dashboard said 'Sync game list success' on staging and then on production (44 games, 44 logos and banners copied to our storage) | R34: The platform's Request Tester sends different fields from its documentation. A header x-decrypt tells which RSA path ran; x-config says why keys are unusable.
A35: 34 | B35: 2026-10-14 | C35: Owner | D35: Investigation | E35: Games / limits | F35: Policy | G35: High | H35: Players can bet up to 100,000 coins per bet and there is no daily loss or win cap. Overnight 23 players bet 13.8M coins and got back 10.6M; 6 of 23 lost more than 50,000 and some ended with almost no coins. | I35: - | J35: Suggested caps: largest bet 10,000, daily loss 50,000, daily win 200,000. Actual: 100,000 / none / none. | K35: Production, game_config | M35: Won't fix | O35: - | P35: Decision | Q35: Owner decision 2026-10-14: keep the existing numbers | R35: Revisit with more data. The limits can be changed at any time on the panel's Games page and apply to the next bet. Other protections stay: 18+ rule, payout cap (100x the bets on that game in 15 minutes), refusal of late or duplicate calls.
A36: 35 | B36: 2026-10-13 | C36: Owner | D36: Investigation | E36: Play Console / games | F36: Policy | G36: High | H36: Confirm that the Play Console content rating and declarations describe the games (simulated casino-style games with purchasable coins, 18+ audience) and that the reviewer notes say the feature is included and turned on from the panel. The games were switched ON for everyone on 2026-10-13 after 1.0.0+8 was approved. | I36: Play Console > App content. | J36: Expected: declarations match the live features. Actual: not confirmed. | K36: Google Play | M36: New | O36: - | P36: Store / console action | Q36: - | R36: The Tulasi guide says outcomes can be adjusted (platform commission, interventions, robot players); the in-app notice says so. A policy strike could affect the whole app.
A37: 36 | B37: 2026-10-13 | C37: Owner | D37: Investigation | E37: Tulasi account | F37: Build/Infra | G37: High | H37: The Tulasi dashboard shows an account Expire Date of 2026-11-22 14:00 (UTC+8). The games stop when it passes unless Tulasi renews it. | I37: Tulasi dashboard, top of the first page. | J37: Expected: renewed before the date. Actual: not yet. | K37: Tulasi dashboard | M37: New | O37: - | P37: Decision | Q37: - | R37: Ask Tulasi about renewal, fees, a failure code for refused calls, and whether Sync Game List can be automatic.
A38: 37 | B38: 2026-10-12 | C38: Owner | D38: Investigation | E38: Security / credentials | F38: Security | G38: Medium | H38: The Tulasi dashboard password was pasted into the chat early in the work, and the first lines of the private-key box were visible in screenshots while setting the keys on staging. Change the password. Rotate the keys with Reset only together with re-setting the secrets on BOTH Supabase projects. | I38: - | J38: Expected: no credential in a chat. Actual: shared once. | K38: Tulasi dashboard | M38: New | O38: - | P38: Decision | Q38: - | R38: The same keys are set on staging and production (one merchant).
A39: 38 | B39: 2026-10-13 | C39: Owner | D39: Investigation | E39: Games on iPhone | F39: Improvement | G39: Low | H39: iPhones show 'coming soon': the games are Android only until the store and legal review for Apple is settled. | I39: - | J39: - | K39: iOS | M39: Needs decision | O39: - | P39: Decision | Q39: - | R39: Apple 5.3 / 4.7 rules for gambling-style content need a separate review.
A40: 39 | B40: 2026-10-13 | C40: Owner | D40: Investigation | E40: Backend (Supabase) | F40: Build/Infra | G40: Critical | H40: Production stalled repeatedly on 13 Oct: background jobs failed to start from 13:43, a 2.5 minute outage at 13:49 after the owner restarted the project, more stalls at 14:05, 14:13, 14:16 and 14:18. Traffic was small (about 8 requests per second, about 10 users): no attack was found. The machine was starved. | I40: scripts/prod/healthcheck.sh: 'could not query the database' or a status call of several seconds. | J40: Expected: status call under 1 s. Actual: up to 7 s and 521/502 errors. | K40: Supabase production, Micro-class compute | M40: Verified | O40: Compute upgraded by the owner at 14:27 IST on 2026-10-13 | P40: Store / console action | Q40: Claude, 2026-10-14 06:40: zero failed jobs for 16 hours; the gate function 7.4 ms to 0.09 ms; CPU test 47 ms (idle staging 50 ms) | R40: Evidence and queries are in HANDOFF.md. Do not restart to fix this. Maintenance ended at 13:26 and 1.0.0+8 reached everyone at once the same afternoon.
...

Sheet Panel
A1: Sr no | B1: Date reported | C1: Reported by | D1: Source | E1: Page / capability | F1: Type | G1: Severity | H1: Issue / Fix | I1: Steps to reproduce | J1: Expected vs actual | K1: Role affected | L1: Browser | M1: Evidence (link) | N1: Status | O1: Assigned to | P1: Fixed in (version / commit) | Q1: Fix needs | R1: Verified by / date | S1: Notes / root cause
A2: 1 | C2: Owner | D2: Owner | E2: Ghost IDs (Super Admin) | F2: Improvement | G2: Medium | H2: Ghost accounts: invisible view-only monitoring logins managed by Super Admin. | I2: - | K2: Super Admin | N2: Released | P2: Oct 3 | Released: live on the admin panel (main b37c27e, 2026-10-13); its database part is applied on production | Q2: Database migration | S2: Edge function ghost-admin deployed. | Status set to Released on 2026-10-14: the panel deploys from main, which now contains this change. Not yet verified by a person.
A3: 2 | C3: Owner | D3: Owner | E3: Live Monitor | F3: Improvement | G3: Medium | H3: Super Admin and Master can watch any live invisibly from the panel (capability monitor_lives). | I3: - | K3: Super Admin, Master | N3: Released | P3: Oct 3 | Released: live on the admin panel (main b37c27e, 2026-10-13); its database part is applied on production | Q3: Panel deploy | S3: Status set to Released on 2026-10-14: the panel deploys from main, which now contains this change. Not yet verified by a person.
A4: 3 | C4: Owner | D4: Owner | E4: Levels | F4: Improvement | G4: Medium | H4: Wealth / Charm levels with XP and a join image, edited by Master. | I4: - | K4: Master | N4: Released | P4: Oct 4 sync batch | Released: live on the admin panel (main b37c27e, 2026-10-13); its database part is applied on production | Q4: Panel deploy | S4: Status set to Released on 2026-10-14: the panel deploys from main, which now contains this change. Not yet verified by a person.
A5: 4 | C5: Owner | D5: Owner | E5: Coin sellers | F5: Improvement | G5: Medium | H5: Coin sellers are linked to real users and show their profile. | I5: - | K5: Master | N5: Released | P5: Oct 4 sync batch | Released: live on the admin panel (main b37c27e, 2026-10-13); its database part is applied on production | Q5: Panel deploy | S5: Status set to Released on 2026-10-14: the panel deploys from main, which now contains this change. Not yet verified by a person.
A6: 5 | C6: Owner | D6: Owner | E6: Support chat | F6: Improvement | G6: Medium | H6: Two-way support chat for Master and Super Admin. | I6: - | K6: Master, Super Admin | N6: Released | P6: Oct 4 sync batch | Released: live on the admin panel (main b37c27e, 2026-10-13); its database part is applied on production | Q6: Panel deploy | S6: Status set to Released on 2026-10-14: the panel deploys from main, which now contains this change. Not yet verified by a person.
A7: 6 | C7: Owner | D7: Owner | E7: Lucky IDs | F7: Improvement | G7: Medium | H7: Lucky ID catalogue. Leading zeros allowed (0786); the app shows the padded ID. | I7: - | K7: Master | N7: Released | P7: 416ac77 / migration 20261005090000 | Released: live on the admin panel (main b37c27e, 2026-10-13); its database part is applied on production | Q7: Database migration | S7: Migration already applied by hand before the push; now recorded. | Status set to Released on 2026-10-14: the panel deploys from main, which now contains this change. Not yet verified by a person.
A8: 7 | C8: Owner | D8: Owner | E8: Users > Bag / Edit profile | F8: Improvement | G8: Medium | H8: Assign entry effect, vehicle, frame, room skin, badge or Lucky ID; edit a user's profile. | I8: - | K8: Master | N8: Released | P8: Oct 4 sync batch | Released: live on the admin panel (main b37c27e, 2026-10-13); its database part is applied on production | Q8: Panel deploy | S8: Status set to Released on 2026-10-14: the panel deploys from main, which now contains this change. Not yet verified by a person.
A9: 8 | C9: Owner | D9: Owner | E9: Staff seats | F9: Improvement | G9: Medium | H9: Master hands a staff seat (with everything it owns) to another user. | I9: - | K9: Master | N9: Released | P9: Oct 4 sync batch | Released: live on the admin panel (main b37c27e, 2026-10-13); its database part is applied on production | Q9: Database migration | S9: Status set to Released on 2026-10-14: the panel deploys from main, which now contains this change. Not yet verified by a person.
A10: 9 | B10: 2026-10-05 | C10: Owner | D10: Owner | E10: Revoked Users | F10: Bug | G10: Medium | H10: Lift revoke restores the account instantly; Super Admin and Master may lift any revoke, including agency-manager revokes. | I10: Revoked Users > Lift revoke | K10: Super Admin, Master | N10: Released | P10: 7bdd076, 4ef891c, f213e62; migrations 20261005120000 and 140000 | Released: live on the admin panel (main b37c27e, 2026-10-13); its database part is applied on production | Q10: Database migration | S10: Migrations recorded in prod on 2026-10-06. | Status set to Released on 2026-10-14: the panel deploys from main, which now contains this change. Not yet verified by a person.
A11: 10 | B11: 2026-10-05 | C11: Owner | D11: Owner | E11: Staff creation | F11: Improvement | G11: Medium | H11: Super Admin may create an agency manager login. | I11: Edit Agency > assign manager | K11: Super Admin | N11: Released | P11: e74cc9e; migration 20261005160000 | Released: live on the admin panel (main b37c27e, 2026-10-13); its database part is applied on production | Q11: Database migration | S11: Status set to Released on 2026-10-14: the panel deploys from main, which now contains this change. Not yet verified by a person.
A12: 11 | B12: 2026-10-05 | C12: Owner | D12: Owner | E12: Edit Agency | F12: Bug | G12: Low | H12: Browser autofill filled manager email/password when assigning a new manager. FIX: ignore autofilled fields when no email; stop password autofill; do not update the manager login. | I12: Edit Agency | K12: Super Admin | N12: Released | P12: 05062b8, a4f31c3 | Released: live on the admin panel (main b37c27e, 2026-10-13); its database part is applied on production | Q12: Panel deploy | S12: Status set to Released on 2026-10-14: the panel deploys from main, which now contains this change. Not yet verified by a person.
A13: 12 | B13: 2026-10-05 | C13: Owner | D13: Owner | E13: Restrict dialog | F13: Bug | G13: Low | H13: Say when a user has no active bans; show load errors. | I13: Users > Restrict | K13: Master | N13: Released | P13: 0c78788 | Released: live on the admin panel (main b37c27e, 2026-10-13); its database part is applied on production | Q13: Panel deploy | S13: Status set to Released on 2026-10-14: the panel deploys from main, which now contains this change. Not yet verified by a person.
A14: 13 | B14: 2026-10-05 | C14: Owner | D14: Owner | E14: Top bar | F14: Bug | G14: Medium | H14: Super Admin saw a meaningless 0 wallet. FIX: shows the treasury; minters see what they can distribute. | I14: Open the panel as Super Admin | K14: Super Admin | N14: Released | P14: cf4d71e | Released: live on the admin panel (main b37c27e, 2026-10-13); its database part is applied on production | Q14: Panel deploy | S14: Status set to Released on 2026-10-14: the panel deploys from main, which now contains this change. Not yet verified by a person.
A15: 14 | B15: 2026-10-05 | C15: Owner | D15: Owner | E15: Agency / Sub / Country panels | F15: Bug | G15: High | H15: Hosts' coins and diamonds showed as 0 for roles that could not read the wallets. FIX: a staff member can read the wallet of a host in an agency they manage; User Management gets a Diamonds column; a wallet a role can't read shows a dash, not a false 0. | I15: Open host lists as an Agency/Sub/Country admin | K15: Agency, Sub, Country | N15: Released | P15: 15be4f6; migration 20261005200000 | Released: live on the admin panel (main b37c27e, 2026-10-13); its database part is applied on production | Q15: Database migration | S15: Policy already existed in prod before the push. | Status set to Released on 2026-10-14: the panel deploys from main, which now contains this change. Not yet verified by a person.
A16: 15 | B16: 2026-10-05 | C16: Investigation | D16: Investigation | E16: Maintenance | F16: Improvement | G16: Medium | H16: When the maintenance window passes and auto-end is off, maintenance stays on silently. Proposal: show a warning on the Maintenance page and a one-click End now. | I16: Start maintenance with auto-end off | J16: Expected: a reminder. Actual: stays locked after the window. | K16: Super Admin | N16: New | Q16: Panel deploy | S16: Seen on 2026-10-05: window ended 19:49 UTC, app stayed locked.
A17: 16 | B17: 2026-10-05 | C17: Investigation | D17: Investigation | E17: Maintenance | F17: Improvement | G17: Medium | H17: 'Log out all users' signed out 126 sessions during the incident and caused a login wave. Proposal: clearer confirmation with the number of sessions it will end. | I17: Maintenance > Log out all | K17: Super Admin | N17: New | Q17: Panel deploy
A18: 17 | C18: Investigation | D18: Investigation | E18: App release settings (new) | F18: Improvement | G18: High | H18: New Super Admin page for the minimum app version, update message and server-side feature switches. | I18: - | K18: Super Admin | N18: In progress | Q18: Panel deploy | S18: Part of the production-safety work. | The Release controls page is live and in use: Games and screen-protection switches saved on 2026-10-13 (audit app_release.changed).
A19: 18 | B19: 2026-10-13 | C19: Owner | D19: Owner | E19: Games (Admin and above) | F19: Improvement | G19: High | H19: Games page: the limits the server enforces (largest bet, daily loss and win, payout multiple, launch lifetime, minimum age), the games received from Tulasi with 'In the app' and 'In Tulasi' status, Hide or Show per game and Show all / Hide all (a Sync never undoes a hide), 14-day totals, two watch reports (winners who then gift, hosts receiving from winners) and every balance call. | I19: - | K19: Super Admin, Master | N19: Released | P19: panel main b37c27e; migrations 20261013100000 to 20261013140000 | Q19: Panel deploy, Database migration | R19: Owner changed the Games switch from the panel 2026-10-13; the Hide / Show buttons were not yet used on production (Claude applied the same change by SQL) | S19: Limits: left at the defaults by the owner's decision on 2026-10-14.
A20: 19 | B20: 2026-10-13 | C20: Owner | D20: Owner | E20: Application Config > Release controls | F20: Improvement | G20: Medium | H20: Release switches 'Games' and 'Block screenshots and screen recording' (feature flags the apps read; both default off). | I20: - | K20: Super Admin | N20: Verified | P20: panel part 1 (5e15bf4) and part 2 (b37c27e) | Q20: Panel deploy | R20: Owner 2026-10-13 (audit log app_release.changed at 13:30:24 on, 13:54:47 off, 14:01:10 on) and Claude (23 players launched games after the switch) | S20: -
A21: 20 | B21: 2026-10-13 | C21: Owner | D21: Owner | E21: Content / Emotes & GIFs, Application Config, landing site | F21: Improvement | G21: Low | H21: Panel release part 1: the Emoji pages are now Emotes & GIFs, a live branding preview in Application Config, and the landing site reads its project from the environment (production by default). | I21: - | K21: Super Admin, Master | N21: Released | P21: panel main 5e15bf4 (2026-10-13) | Q21: Panel deploy | R21: - | S21: Checked on the live bundle: new text present, none of the part-2 names.
A22: 21 | B22: 2026-10-13 | C22: Owner | D22: Owner | E22: Store / Coins / Lucky Box | F22: Improvement | G22: Medium | H22: Panel release part 2: effect play speed and sound fields on entry effects, vehicles and gifts; Lucky Box cooldown (hours) field. | I22: - | K22: Master | N22: Released | P22: panel main b37c27e; migrations 20261009120000, 20261010090000 | Q22: Panel deploy, Database migration | R22: - | S22: Applied on production 2026-10-13.
A23: 22 | B23: 2026-10-13 | C23: Investigation | D23: Investigation | E23: View user profile > assign / remove | F23: Bug | G23: Medium | H23: The panel code for assign and remove on View user profile reached production on 2026-10-12, but its migration 20261012100000 did not, so removing a badge or frame would fail with 'function not found'. FIX: the migration was applied on 2026-10-13 07:19 UTC. | I23: - | K23: Super Admin, Master | N23: Released | P23: migration 20261012100000 | Q23: Database migration | R23: - | S23: Found by Claude during the part-1 release check; staff-only.
A24: 23 | B24: 2026-10-11 | C24: Owner | D24: Owner | E24: Top bar | F24: Improvement | G24: Medium | H24: Master and Super Admin can switch the panel between the production and staging projects (each keeps its own session; staging shows an orange strip). | I24: - | K24: Super Admin, Master | N24: Released | P24: panel main 2778960 (2026-10-11) | Q24: Panel deploy | R24: - | S24: Needs the two staging variables in Vercel (set).

Sheet Lists
A1: Type | B1: Severity | C1: Status | D1: Fix needs | E1: Source | G1: To change a dropdown, edit the list in its column. Keep each list contiguous (no blank cells in the middle).
A2: Bug | B2: Critical | C2: New | D2: None | E2: Owner
A3: Fix | B3: High | C3: Confirmed | D3: Database migration | E3: Play user
A4: Improvement | B4: Medium | C4: In progress | D4: Edge function | E4: Play Console
A5: Security | B5: Low | C5: Needs decision | D5: App build | E5: App Review
A6: Policy | C6: Fixed (in code) | D6: Panel deploy | E6: QA tester
A7: Build/Infra | C7: Released | D7: Store / console action | E7: Panel user
A8: Question | C8: Verified | D8: Decision | E8: Investigation
C9: Closed
C10: Can't reproduce
C11: Won't fix
